Workbook

Sheet solicitudes
A1: Id | B1: Proyecto | D1: Punto de conexión y Nivel de tensión (kV) | E1: Tipo (SAC/SUCTD) | F1: Estado | G1: Zona | H1: Clasificación (C1, C2, C3) | I1: Observación | J1: NUP | K1: Empresa Solicitante | L1: Tipo | M1: Estado Solicitud | N1: Fecha Recepción | O1: Capacidad [MW] | P1: Tipo Proyecto | Q1: Fecha Estimada Conexión | R1: Punto de Conexión | S1: Nivel de tension | T1: Barra | U1: Paño | V1: Región | W1: Comuna | X1: Segmento de Transmisión | Y1: Fecha emisión informe definitivo | Z1: Plazo obtención declaración en const | AA1: Prórroga plazo obtención declaración en const.
A2: 2662 | B2: BESS Monte Águila | K2: Grenergy Renovables Pacific Limitada | L2: SUCTD | M2: Solicitud ingresada | N2: 22 de julio de 2025 11:23:32 | O2: 240 | P2: Híbrido | Q2: 22 de enero de 2027 00:00:00 | R2: S/E Elevadora Monte Águila 33/220 kV | S2: 33 | T2: Barra media tensión | U2: por definir | V2: Biobío | W2: Cabrero | X2: Dedicada
A3: 2646 | B3: Retiros de Red CRCA Víctor Jara | K3: Grenergy Renovables Pacific Limitada | L3: FEHACIENTES | M3: Desistida | N3: 10 de julio de 2025 10:51:20 | O3: 200 | P3: Híbrido | Q3: 30 de septiembre de 2025 00:00:00 | R3: S/E Elevadora PFV Victor Jara | S3: 33 | T3: BP | U3: TBD | V3: Tarapacá | W3: Pozo Almonte | X3: Dedicada
A4: 2424 | B4: PFV Pinina | J4: 5534 | K4: Grenergy Renovables Pacific Limitada | L4: SAC | M4: Detenida a la espera de definición de ingeniería de la obra | N4: 6 de febrero de 2025 18:01:12 | O4: 90 | P4: Híbrido | Q4: 30 de julio de 2030 00:00:00 | R4: NUEVA S/E VALENTÍN LETELIER 154 | S4: 154 | T4: Barra principal | U4: por definir | V4: Maule | W4: Linares | X4: Nacional
A5: 2421 | B5: PFV SAMARA | J5: 5546 | K5: Grenergy Renovables Pacific Limitada | L5: SAC | M5: Rechazada | N5: 6 de febrero de 2025 17:58:03 | O5: 200 | P5: Híbrido | Q5: 30 de julio de 2030 00:00:00 | R5: NUEVA S/E MANUEL RODRIGUEZ | S5: 220 | T5: Barra Principal | U5: por definir | V5: Metropolitana de Santiago | W5: Tiltil | X5: Nacional
A6: 2418 | B6: PFV TAEL | J6: 5544 | K6: Grenergy Renovables Pacific Limitada | L6: SAC | M6: Rechazada | N6: 6 de febrero de 2025 17:56:45 | O6: 200 | P6: Híbrido | Q6: 31 de julio de 2030 00:00:00 | R6: MANUEL RODRIGUEZ 220 [kV] | S6: 220 | T6: Barra Principal | U6: por definir | V6: Metropolitana de Santiago | W6: Tiltil | X6: Nacional
A7: 2416 | B7: PFV JAOS | J7: 5536 | K7: Grenergy Renovables Pacific Limitada | L7: SAC | M7: Detenida a la espera de definición de ingeniería de la obra | N7: 6 de febrero de 2025 17:54:47 | O7: 90 | P7: Híbrido | Q7: 30 de julio de 2030 00:00:00 | R7: NUEVA S/E LLOLLEO 110 | S7: 110 | T7: Barra Principal | U7: Por definir | V7: Valparaiso | W7: San Antonio | X7: Nacional
A8: 2415 | B8: PFV DENEB | J8: 5545 | K8: Grenergy Renovables Pacific Limitada | L8: SAC | M8: Detenida a la espera de definición de ingeniería de la obra | N8: 6 de febrero de 2025 17:51:34 | O8: 90 | P8: Híbrido | Q8: 30 de julio de 2030 00:00:00 | R8: NUEVA S/E RELONCAVÍ 110 | S8: 110 | T8: Barra Principal | U8: Por definir | V8: Los Lagos | W8: Puerto Montt | X8: Nacional
A9: 2414 | B9: PFV Encina | J9: 5547 | K9: Grenergy Renovables Pacific Limitada | L9: SAC | M9: Detenida a la espera de definición de ingeniería de la obra | N9: 6 de febrero de 2025 17:48:30 | O9: 90 | P9: Híbrido | Q9: 30 de julio de 2030 00:00:00 | R9: NUEVA S/E VALENTÍN LETELIER 66 kV | S9: 66 | T9: Barra Principal | U9: por definir | V9: Maule | W9: Linares | X9: Nacional
A10: 2405 | B10: PFV AMAYA | J10: 5550 | K10: Grenergy Renovables Pacific Limitada | L10: SAC | M10: Detenida a la espera de definición de ingeniería de la obra | N10: 6 de febrero de 2025 17:44:29 | O10: 90 | P10: Híbrido | Q10: 31 de julio de 2030 00:00:00 | R10: S/E NOS 110 [kV] | S10: 110 | T10: Barra principal | U10: Por definir | V10: Metropolitana de Santiago | W10: San Bernardo | X10: Nacional
A11: 2242 | B11: PFV El Vencedor II | J11: 5360 | K11: Grenergy Renovables Pacific Limitada | L11: SAC | M11: Rechazada | N11: 22 de noviembre de 2024 16:14:23 | O11: 800 | P11: Híbrido | Q11: 30 de julio de 2030 00:00:00 | R11: PFV Vencedor II | S11: 220 | T11: Nueva Diagonal | U11: Por Definir | V11: Antofagasta | W11: Taltal | X11: Nacional
A12: 2240 | B12: PFV El Vencedor 1 | J12: 5362 | K12: Grenergy Renovables Pacific Limitada | L12: SAC | M12: Rechazada | N12: 22 de noviembre de 2024 16:14:21 | O12: 400 | P12: Híbrido | Q12: 30 de julio de 2030 00:00:00 | R12: S/E Parinas 220 kV | S12: 220 | T12: Nueva Media Diagonal | U12: Por Definir | V12: Antofagasta | W12: Taltal | X12: Nacional
A13: 2237 | B13: PFV Vanz | J13: 5369 | K13: Grenergy Renovables Pacific Limitada | L13: SAC | M13: Detenida a la espera de definición de ingeniería de la obra | N13: 22 de noviembre de 2024 16:14:18 | O13: 200 | P13: Híbrido | Q13: 30 de julio de 2030 00:00:00 | R13: S/E Monte Mina 220 kV | S13: 220 | T13: Por definir | U13: Por Definir | V13: Antofagasta | W13: Antofagasta | X13: Nacional
A14: 2238 | B14: PFV TITÁN | J14: 5358 | K14: Grenergy Renovables Pacific Limitada | L14: SAC | M14: Detenida a la espera de definición de ingeniería de la obra | N14: 22 de noviembre de 2024 16:14:18 | O14: 200 | P14: Híbrido | Q14: 31 de julio de 2030 00:00:00 | R14: S/E Entre Ríos 220 kV | S14: 220 | T14: TBD | U14: TBD | V14: Biobío | W14: Cabrero | X14: Nacional
A15: 2236 | B15: PFV ATOM | J15: 5370 | K15: Grenergy Renovables Pacific Limitada | L15: SAC | M15: Rechazada | N15: 22 de noviembre de 2024 16:14:17 | O15: 200 | P15: Híbrido | Q15: 30 de junio de 2030 00:00:00 | R15: S/E Entre Ríos 220 kV | S15: 220 | T15: TBD | U15: TBD | V15: Biobío | W15: Cabrero | X15: Nacional
A16: 2235 | B16: PFV TARVOS | J16: 5361 | K16: Grenergy Renovables Pacific Limitada | L16: SAC | M16: Rechazada | N16: 22 de noviembre de 2024 16:14:16 | O16: 200 | P16: Híbrido | Q16: 30 de junio de 2030 00:00:00 | R16: S/E Kimal 220 kV | S16: 220 | T16: TBD | U16: TBD | V16: Antofagasta | W16: Maria Elena | X16: Nacional
A17: 2234 | B17: PFV FOBOS | K17: Grenergy Renovables Pacific Limitada | L17: SAC | M17: Rechazada | N17: 22 de noviembre de 2024 16:14:15 | O17: 700 | P17: Híbrido | Q17: 30 de junio de 2030 00:00:00 | R17: S/E Kimal 220 kV | S17: 220 | T17: TBD | U17: TBD | V17: Antofagasta | W17: Maria Elena | X17: Nacional
A18: 2068 | B18: BESS Víctor Jara 200 MW 6.5 horas | J18: 5065 | K18: Grenergy Renovables Pacific Limitada | L18: FEHACIENTES | M18: Proyecto declarado en construccion | N18: 19 de julio de 2024 09:33:07 | O18: 200 | P18: Híbrido | Q18: 31 de enero de 2026 00:00:00 | R18: S/E Victor Jara 33 kV | S18: 33 | T18: BP | U18: TBD | V18: Tarapacá | W18: Pozo Almonte | X18: Dedicada | Z18: 02/2025
A19: 1919 | B19: BESS ORTOSIA | J19: 4814 | K19: Grenergy Renovables Pacific Limitada | L19: SAC | M19: Observaciones a Informe de Autorización de Conexión Preliminar | N19: 27 de marzo de 2024 13:06:12 | O19: 90 | P19: Híbrido | Q19: 31 de marzo de 2028 00:00:00 | R19: S/E Torquemada 110 KV | S19: 110 | T19: Barra Principal | U19: Por definir | V19: Valparaiso | W19: Concón | X19: Zonal
A20: 1912 | B20: PFV + BESS Triqueta | J20: 4806 | K20: Grenergy Renovables Pacific Limitada | L20: SUCTD | M20: Rechazada | N20: 19 de marzo de 2024 17:30:57 | O20: 130 | P20: Híbrido | Q20: 31 de agosto de 2026 00:00:00 | R20: S/E Triqueta entre las estructuras 112 y 113 de la línea Quillota - Piuquenes en 220 kV | S20: 220 | T20: Barra Principal | U20: JT1 | V20: Valparaiso | W20: Catemu | X20: Dedicada
A21: 1911 | B21: BESS Metis | J21: 4805 | K21: Grenergy Renovables Pacific Limitada | L21: SAC | M21: Proyecto autorizado para declararse en construcción | N21: 18 de marzo de 2024 11:55:07 | O21: 90 | P21: Híbrido | Q21: 31 de marzo de 2028 00:00:00 | R21: S/E Quillota 110 [kV] | S21: 110 | T21: Barra Principal | U21: Por definir | V21: Valparaiso | W21: Quillota | X21: Nacional | Y21: 26/12/2024 12:16:05 | Z21: 12/2026
A22: 1904 | B22: BESS Telesto II | J22: 4790 | K22: Grenergy Renovables Pacific Limitada | L22: SAC | M22: Proyecto autorizado para declararse en construcción | N22: 14 de marzo de 2024 14:49:31 | O22: 20 | P22: Híbrido | Q22: 31 de marzo de 2028 00:00:00 | R22: S/E Salamanca 23 [kV] | S22: 23 | T22: Barra Principal N°2 | U22: Nuevo Paño E8 | V22: Coquimbo | W22: Salamanca | X22: Zonal | Y22: 16/12/2024 08:40:55 | Z22: 12/2026
A23: 1865 | B23: Bess Kore | J23: 4734 | K23: Grenergy Renovables Pacific Limitada | L23: SAC | M23: Observaciones a Informe de Autorización de Conexión Preliminar | N23: 13 de febrero de 2024 11:20:35 | O23: 90 | P23: Híbrido | Q23: 31 de marzo de 2028 00:00:00 | R23: S/E Alto Jahuel 110 [kV] | S23: 110 | T23: Barra Principal | U23: Por definir | V23: Metropolitana de Santiago | W23: Buin | X23: Nacional
A24: 1864 | B24: Bess Carpo | J24: 4735 | K24: Grenergy Renovables Pacific Limitada | L24: SAC | M24: Proyecto autorizado para declararse en construcción | N24: 13 de febrero de 2024 11:12:44 | O24: 150 | P24: Híbrido | Q24: 31 de marzo de 2028 00:00:00 | R24: S/E Alto Jahuel 154 [kV] | S24: 154 | T24: Barra Principal | U24: Por Definir | V24: Metropolitana de Santiago | W24: Buin | X24: Nacional | Y24: 21/01/2025 18:32:23 | Z24: 01/2027
A25: 1863 | B25: BESS Tebe | J25: 4732 | K25: Grenergy Renovables Pacific Limitada | L25: SAC | M25: Observaciones a Informe de Autorización de Conexión Preliminar | N25: 13 de febrero de 2024 10:58:31 | O25: 200 | P25: Híbrido | Q25: 31 de marzo de 2028 00:00:00 | R25: S/E Alto Jahuel 220 kV | S25: 220 | T25: Barra Principal | U25: Por Definir | V25: Metropolitana de Santiago | W25: Buin | X25: Nacional
A26: 1856 | B26: BESS Elara | J26: 4723 | K26: Grenergy Renovables Pacific Limitada | L26: SAC | M26: Detenida a la espera de definición de ingeniería de la obra | N26: 9 de febrero de 2024 10:24:30 | O26: 90 | P26: Híbrido | Q26: 31 de marzo de 2028 00:00:00 | R26: S/E Totihue 66 kV | S26: 66 | T26: Barra Principal | U26: Por Definir | V26: Libertador General Bernardo OHiggins | W26: Rengo | X26: Zonal
A27: 1850 | B27: BESS Cálice | J27: 4718 | K27: Grenergy Renovables Pacific Limitada | L27: SAC | M27: Elaboración Informe de Autorización de Conexión Preliminar | N27: 2 de febrero de 2024 10:02:12 | O27: 90 | P27: Híbrido | Q27: 31 de marzo de 2028 00:00:00 | R27: S/E Caldera 110 kV | S27: 110 | T27: Barra Principal | U27: H4 | V27: Atacama | W27: Caldera | X27: Zonal
A28: 1827 | B28: BESS Calé | J28: 4684 | K28: Grenergy Renovables Pacific Limitada | L28: SAC | M28: Proyecto autorizado para declararse en construcción | N28: 12 de enero de 2024 01:04:04 | O28: 90 | P28: Híbrido | Q28: 31 de marzo de 2028 00:00:00 | R28: S/E Bajos de Mena 110 kV | S28: 110 | T28: Barra Principal | U28: Por definir | V28: Metropolitana de Santiago | W28: Puente Alto | X28: Zonal | Y28: 10/10/2024 11:18:10 | Z28: 10/2026
A29: 1826 | B29: BESS Hiperion | J29: 4683 | K29: Grenergy Renovables Pacific Limitada | L29: SAC | M29: Desarrollo de estudios y/o antecedentes | N29: 11 de enero de 2024 23:31:36 | O29: 90 | P29: Híbrido | Q29: 31 de marzo de 2028 00:00:00 | R29: S/E Las Canteras (Ex S/E Seccionadora Colina) 110 kV | S29: 110 | T29: Barra Principal | U29: por definir | V29: Metropolitana de Santiago | W29: Quilicura | X29: Zonal
A30: 1792 | B30: Ampliación PMG Yellowstone | J30: 4647 | K30: Grenergy Renovables Pacific Limitada | L30: FEHACIENTES | M30: Proyecto autorizado para declararse en construcción | N30: 18 de diciembre de 2023 12:56:49 | O30: 9 | P30: Híbrido | Q30: 30 de abril de 2025 00:00:00 | R30: S/E Yellowstone 13,2 kV | S30: 13 | T30: Barra Principal | U30: Por definir | V30: Libertador General Bernardo OHiggins | W30: Marchigüe | X30: Dedicada | Z30: 12/2024
A31: 1790 | B31: Ampliación BESS Gabriela 220 MW | J31: 4636 | K31: Grenergy Renovables Pacific Limitada | L31: FEHACIENTES | M31: Proyecto declarado en construccion | N31: 14 de diciembre de 2023 15:38:28 | O31: 220 | P31: Híbrido | Q31: 30 de junio de 2025 00:00:00 | R31: S/E Elevadora PFV Gabriela 33 kV | S31: 33 | T31: Barra Principal | U31: Por definir | V31: Antofagasta | W31: Sierra Gorda | X31: Dedicada | Z31: 07/2024
A32: 1789 | B32: BESS Víctor Jara 200 MW | J32: 4635 | K32: Grenergy Renovables Pacific Limitada | L32: FEHACIENTES | M32: Proyecto declarado en construccion | N32: 14 de diciembre de 2023 15:31:58 | O32: 200 | P32: Híbrido | Q32: 31 de enero de 2027 00:00:00 | R32: S/E Elevadora PFV Víctor Jara 33 kV | S32: 33 | T32: Barra Principal | U32: por definir | V32: Tarapacá | W32: Pozo Almonte | X32: Dedicada | Z32: 01/2026
A33: 1763 | B33: PFV Triqueta | J33: 4595 | K33: Grenergy Renovables Pacific Limitada | L33: SUCTD | M33: Rechazada | N33: 24 de noviembre de 2023 13:52:38 | O33: 130 | P33: Híbrido | Q33: 31 de agosto de 2026 00:00:00 | R33: Linea Quillota - Piuquenes | S33: 220 | T33: Barra Principal | U33: por definir | V33: Valparaiso | W33: Catemu | X33: Dedicada | Y33: 19/03/2024 17:36:18 | Z33: 03/2024
A34: 1735 | B34: BESS Sao | J34: 4566 | K34: Grenergy Renovables Pacific Limitada | L34: SAC | M34: Detenida a la espera de definición de ingeniería de la obra | N34: 3 de noviembre de 2023 20:22:04 | O34: 200 | P34: Híbrido | Q34: 30 de junio de 2027 00:00:00 | R34: S/E Tinguiririca 220 kV | S34: 220 | T34: Media diagonal | U34: por definir | V34: Libertador General Bernardo OHiggins | W34: Placilla | X34: Nacional
A35: 1734 | B35: BESS Nereida | J35: 4567 | K35: Grenergy Renovables Pacific Limitada | L35: SAC | M35: Detenida a la espera de definición de ingeniería de la obra | N35: 3 de noviembre de 2023 20:02:38 | O35: 90 | P35: Híbrido | Q35: 30 de junio de 2027 00:00:00 | R35: S/E Seccionadora El Guindal 110 kV | S35: 110 | T35: Barra Principal | U35: por definir | V35: Metropolitana de Santiago | W35: Buin | X35: Zonal
A36: 1732 | B36: Bess Proteo | K36: Grenergy Renovables Pacific Limitada | L36: SAC | M36: Desistida | N36: 3 de noviembre de 2023 20:00:57 | O36: 200 | P36: Híbrido | Q36: 30 de junio de 2027 00:00:00 | R36: Tinguiririca 220 kV | S36: 220 | T36: Media Diagonal | U36: por definir | V36: Libertador General Bernardo OHiggins | W36: Placilla | X36: Nacional
A37: 1730 | B37: BESS Proteo | J37: 4554 | K37: Grenergy Renovables Pacific Limitada | L37: SAC | M37: Detenida a la espera de definición de ingeniería de la obra | N37: 3 de noviembre de 2023 19:55:51 | O37: 50 | P37: Híbrido | Q37: 30 de junio de 2027 00:00:00 | R37: S/E Santa Cruz 66 kV | S37: 66 | T37: Barra principal | U37: por definir | V37: Libertador General Bernardo OHiggins | W37: Santa Cruz | X37: Zonal
A38: 1729 | B38: BESS Despina | J38: 4545 | K38: Grenergy Renovables Pacific Limitada | L38: SAC | M38: Detenida a la espera de definición de ingeniería de la obra | N38: 3 de noviembre de 2023 19:54:53 | O38: 90 | P38: Híbrido | Q38: 30 de junio de 2027 00:00:00 | R38: S/E Pachacama 110 kV | S38: 110 | T38: Barra Principal | U38: por definir | V38: Valparaiso | W38: La Calera | X38: Nacional
A39: 1727 | B39: 200 | K39: Grenergy Renovables Pacific Limitada | L39: SAC | M39: Desistida | N39: 3 de noviembre de 2023 19:51:22 | O39: 200 | P39: Híbrido | Q39: 30 de junio de 2027 00:00:00 | R39: Tinguiririca 220 kV | S39: 220 | T39: media diagonal | U39: por definir | V39: Libertador General Bernardo OHiggins | W39: Placilla | X39: Nacional
A40: 1726 | B40: BESS Talasa | J40: 4529 | K40: Grenergy Renovables Pacific Limitada | L40: SAC | M40: Detenida a la espera de definición de ingeniería de la obra | N40: 3 de noviembre de 2023 19:49:45 | O40: 90 | P40: Híbrido | Q40: 30 de junio de 2027 00:00:00 | R40: S/E El Pimiento 110kV | S40: 110 | T40: Barra Principal | U40: por definir | V40: Metropolitana de Santiago | W40: Melipilla | X40: Nacional
...

Sheet lista
B3: Region | C3: Macrozona
B4: 2. Tarapacá | C4: Norte
B5: 3. Antofagasta | C5: Norte
B6: 4. Atacama | C6: Norte
B7: 5. Coquimbo | C7: Norte
B8: 6. Valparaiso | C8: Centro
B9: 7. Metropolitana | C9: Centro
B10: 8. O´Higgins | C10: Centro
B11: 9. Maule | C11: Centro
B12: 11. BioBio | C12: Sur
B13: 12. La Araucania | C13: Sur
B14: 13. Los Rios | C14: Sur
B15: 14. Los Lagos | C15: Sur

Sheet Analisis SE 2025
B2: Id | C2: Proyecto | D2: Punto de conexión y Nivel de tensión (kV) | E2: Capacidad [MW] Solicitada | F2: Región | G2: Tecnología | H2: Tipo (SAC/SUCTD) | I2: Estado Tramitación | J2: Macro Zona | K2: Clasificación (C1, C2, C3) | L2: Observacion | M2: ¿Permite reconversión? | N2: Comentario adicional
B3: 1919 | C3: BESS Ortosia | D3: S/E Torquemada 110 KV | E3: 90 | F3: 6. Valparaiso | G3: BESS | H3: SAC | I3: Observaciones a Informe de Autorización de Conexión Preliminar. | J3: =VLOOKUP(F3,lista!$B$4:$C$15,2,FALSE) -> Centro | K3: C2 | L3: Proyecto en tramitación ante el CEN. A la espera de emisión de informes. | M3: No | N3: Terreno prospectado
B4: 1598 | C4: BESS Varón | D4: S/E La Pólvora 220 kV | E4: 90 | F4: 6. Valparaiso | G4: BESS | H4: SAC | I4: En espera de definición de ingeniería CEN | J4: =VLOOKUP(F4,lista!$B$4:$C$15,2,FALSE) -> Centro | K4: C2 | L4: Proyecto en etapa temprana. En espera que adjudicatario de las obras de ampliación avance con ingeniería. | M4: Si
B5: 1865 | C5: Bess Kore | D5: S/E Alto Jahuel 110 [kV] | E5: 90 | F5: 7. Metropolitana | G5: BESS | H5: SAC | I5: Observaciones a Informe de Autorización de Conexión Preliminar | J5: =VLOOKUP(F5,lista!$B$4:$C$15,2,FALSE) -> Centro | K5: C2 | L5: Proyecto BESS SA en estado avanzado, se insiste al CEN para emisión del Informe Definitivo. | M5: No
B6: 1864 | C6: Bess Carpo | D6: S/E Alto Jahuel 154 [kV] | E6: 150 | F6: 7. Metropolitana | G6: BESS | H6: SAC | I6: Proyecto autorizado para declararse en construcción | J6: =VLOOKUP(F6,lista!$B$4:$C$15,2,FALSE) -> Centro | K6: C2 | L6: Proyecto BESS SA en estado avanzado, en espera para Declararse en Construcción. | M6: No
B7: 1827 | C7: BESS Calé | D7: S/E Bajos de Mena 110 kV | E7: 90 | F7: 7. Metropolitana | G7: BESS | H7: SAC | I7: Proyecto autorizado para declararse en construcción | J7: =VLOOKUP(F7,lista!$B$4:$C$15,2,FALSE) -> Centro | K7: C2 | L7: Proyecto BESS SA en estado avanzado, en espera para Declararse en Construcción. | M7: No | N7: Terreno proespectado, limitacion de plazo de conexión (propietario)
B8: 1826 | C8: BESS Hiperion | D8: S/E Las Canteras (Ex S/E Seccionadora Colina) 110 kV | E8: 90 | F8: 7. Metropolitana | G8: BESS | H8: SAC | I8: Desarrollo de estudios y/o antecedentes | J8: =VLOOKUP(F8,lista!$B$4:$C$15,2,FALSE) -> Centro | K8: C2 | L8: Proyecto en tramitación ante el CEN. | M8: Si | N8: Terreno costoso y datacenters en al zona
B9: 1275 | C9: PFV La Ruca | D9: S/E Seccionadora La Ruca 110 kV | E9: 100 | F9: 5. Coquimbo | G9: PFV + BESS | H9: SAC | I9: En espera de definición de ingeniería CEN | J9: =VLOOKUP(F9,lista!$B$4:$C$15,2,FALSE) -> Norte | K9: C3 | L9: Proyecto en etapa temprana. En espera que adjudicatario de las obras de ampliación avance con ingeniería. | M9: Si
B10: 2416 | C10: PFV JAOS | D10: NUEVA S/E LLOLLEO 110 | E10: 90 | F10: 6. Valparaiso | G10: PFV + BESS | H10: SAC | I10: En espera de definición de ingeniería CEN | J10: =VLOOKUP(F10,lista!$B$4:$C$15,2,FALSE) -> Centro | K10: C3 | L10: Proyecto en etapa temprana. En espera que adjudicatario de las obras de ampliación avance con ingeniería. | M10: Si
B11: 1729 | C11: BESS Despina | D11: S/E Pachacama 110 kV | E11: 90 | F11: 6. Valparaiso | G11: BESS | H11: SAC | I11: En espera de definición de ingeniería CEN | J11: =VLOOKUP(F11,lista!$B$4:$C$15,2,FALSE) -> Centro | K11: C3 | L11: Proyecto en etapa temprana. En espera que adjudicatario de las obras de ampliación avance con ingeniería. | M11: Si
B12: 1726 | C12: BESS Talasa | D12: S/E El Pimiento 110kV | E12: 90 | F12: 7. Metropolitana | G12: BESS | H12: SAC | I12: En espera de definición de ingeniería CEN | J12: =VLOOKUP(F12,lista!$B$4:$C$15,2,FALSE) -> Centro | K12: C3 | L12: Proyecto en etapa temprana. En espera que adjudicatario de las obras de ampliación avance con ingeniería. | M12: Si
B13: 1723 | C13: BESS Neso | D13: S/E Linderos 154 kV | E13: 150 | F13: 7. Metropolitana | G13: BESS | H13: SAC | I13: En espera de definición de ingeniería CEN | J13: =VLOOKUP(F13,lista!$B$4:$C$15,2,FALSE) -> Centro | K13: C3 | L13: Proyecto en etapa temprana. En espera que adjudicatario de las obras de ampliación avance con ingeniería. | M13: Si
B14: 1700 | C14: BESS Tritón | D14: S/E Seccionadora El Pimiento 220 kV | E14: 200 | F14: 7. Metropolitana | G14: BESS | H14: SAC | I14: En espera de definición de ingeniería CEN | J14: =VLOOKUP(F14,lista!$B$4:$C$15,2,FALSE) -> Centro | K14: C3 | L14: Proyecto en etapa temprana. En espera que adjudicatario de las obras de ampliación avance con ingeniería. | M14: Si
B15: 1730 | C15: BESS Proteo | D15: S/E Santa Cruz 66 kV | E15: 50 | F15: 8. O´Higgins | G15: BESS | H15: SAC | I15: En espera de definición de ingeniería CEN | J15: =VLOOKUP(F15,lista!$B$4:$C$15,2,FALSE) -> Centro | K15: C3 | L15: Proyecto en etapa temprana. En espera que adjudicatario de las obras de ampliación avance con ingeniería. | M15: Si
B16: 2414 | C16: PFV Encina | D16: NUEVA S/E VALENTÍN LETELIER 66 kV | E16: 90 | F16: 9. Maule | G16: PFV + BESS | H16: SAC | I16: En espera de definición de ingeniería CEN | J16: =VLOOKUP(F16,lista!$B$4:$C$15,2,FALSE) -> Centro | K16: C3 | L16: Proyecto en etapa temprana. En espera que adjudicatario de las obras de ampliación avance con ingeniería. | M16: Si
C18: Notas:
C19: - Los proyectos Clasificación "C2" podrían realizar una hibridación con Data Center una vez se Declaración en Construcción, resultando finalmente un proyecto del tipo Data Center + BESS.
C20: - Los proyectos clasificación "C3" podrían realizar una reconversión de teccnología sin necesidad de tener una Declaración en Construcción pudiendo resultar en un proyecto Data Center, Data Center + BESS u otro.
C22: Garantias: Para proyectos C2, la garantia esta comprometida a la conexión del proyecto. Proyectos en C3 es posible

Sheet DC Acceso abierto 2025
A2: ACCESO ABIERTO | B2: Proyecto | C2: NUP | D2: Empresa Solicitante | E2: Tipo | F2: Estado Solicitud | G2: Fecha Recepción | H2: Capacidad [MW] | I2: Tipo Proyecto | J2: Fecha Estimada Conexión | K2: Punto de Conexión | L2: Nivel de tension | M2: Barra | N2: Paño | O2: Región | P2: Comuna | Q2: Segmento de Transmisión | R2: Fecha emisión informe definitivo | S2: Plazo obtención declaración en const | T2: Prórroga plazo obtención declaración en const.
A3: 537 | B3: PROYECTO ODATA DATACENTER ST01 | C3: 2129 | D3: ODATA CHILE S.A. | E3: SAC | F3: Proyecto declarado en construcción | G3: 20 de julio de 2020 12:59:33 | H3: 30 | I3: Consumo | J3: 30 de junio de 2022 00:00:00 | K3: S/E Nueva Lampa 220 kV | L3: 220 | M3: Ambas Barras | N3: J7/J8 (Diagonal Nº3) | O3: Metropolitana de Santiago | P3: Lampa | Q3: Nacional | R3: 05/07/2023 15:44:07 | S3: 01/2024
A4: 854 | B4: ODATA DC ST02 | D4: ODATA CHILE S.A. | E4: SAC | F4: Rechazada | G4: 22 de marzo de 2021 21:05:24 | H4: 60 | I4: Consumo | J4: 30 de noviembre de 2023 00:00:00 | K4: S/E LO ESPEJO 110 kV | L4: 110 | M4: BARRAS 1 Y 2 | N4: 2 NUEVOS PAÑOS A CONSTRUIR | O4: Metropolitana de Santiago | P4: San Bernardo | Q4: Zonal
A5: 888 | B5: Datacenter Condor | C5: 2597 | D5: Microsoft Datacenter Chile SA | E5: SAC | F5: Desistida | G5: 13 de abril de 2021 14:34:17 | H5: 25 | I5: Consumo | J5: 1 de mayo de 2023 00:00:00 | K5: S/E Chacabuco 110kv | L5: 110 | M5: Doble Barra | N5: H3, H4 | O5: Metropolitana de Santiago | P5: Quilicura | Q5: Zonal | R5: 29/06/2022 10:32:23 | S5: 12/2022
A6: 1009 | B6: Datacenter Pisco | C6: 2801 | D6: Microsoft Datacenter Chile SA | E6: SAC | F6: Rechazada | G6: 27 de julio de 2021 15:10:55 | H6: 40 | I6: Consumo | J6: Fecha inválida | K6: S/E Chicureo 220 kV | L6: 220 | M6: Barra 1 y 2 | N6: J3, J4 | O6: Metropolitana de Santiago | P6: Colina | Q6: Zonal
A7: 1043 | B7: Datacenter Milagros | C7: 3000 | D7: Microsoft Datacenter Chile SA | E7: SUCTD | F7: Rechazada | G7: 8 de octubre de 2021 13:24:40 | H7: 40 | I7: Consumo | J7: 4 de julio de 2023 00:00:00 | K7: S/E Lampa | L7: 220 | M7: Barra Principal, seccion 1 y seccion 2 | N7: J3, J4 | O7: Metropolitana de Santiago | P7: Lampa | Q7: Dedicada | R7: 02/06/2023 12:20:44 | S7: 09/2024
A8: 1049 | B8: EDCSCL02_COLINA | D8: Edgeconnex Chile V SpA | E8: SAC | F8: Desistida | G8: 15 de octubre de 2021 16:08:01 | H8: 30 | I8: Consumo | J8: 15 de julio de 2023 00:00:00 | K8: S/E COLINA 110KV | L8: 110 | M8: DOBLE BARRA | N8: Por Definir | O8: Metropolitana de Santiago | P8: Colina | Q8: Zonal
A9: 1094 | B9: SCALA - Fase Inicial Sta Teresa DC | C9: 3156 | D9: Electrica Santa Teresa SpA | E9: SUCTD | F9: Rechazada | G9: 30 de diciembre de 2021 07:06:54 | H9: 20 | I9: Consumo | J9: 27 de septiembre de 2022 00:00:00 | K9: SE Lampa | L9: 23 | M9: Barra 1 y Barra 2 | N9: E1 y E2 | O9: Metropolitana de Santiago | P9: Lampa | Q9: Dedicada
A10: 1127 | B10: DC Huechuraba - Fase 1 | C10: 3384 | D10: Electrica Huechuraba SpA | E10: SAC | F10: Rechazada | G10: 1 de abril de 2022 15:19:18 | H10: 10 | I10: Consumo | J10: 6 de enero de 2023 00:00:00 | K10: S/E Recoleta 12 kV | L10: 12 | M10: Barra Principal N°3 y Barra Principal N°4 | N10: E21 (5-T3) y E30 (6-T4) | O10: Metropolitana de Santiago | P10: Huechuraba | Q10: Zonal
A11: 1130 | B11: DC Huechuraba - Fase 2 | C11: 3391 | D11: Electrica Huechuraba SpA | E11: SAC | F11: Rechazada | G11: 6 de abril de 2022 14:38:47 | H11: 60 | I11: Consumo | J11: 3 de noviembre de 2024 00:00:00 | K11: S/E El Salto 110 kV | L11: 110 | M11: Barras 1 y 2 Sección N°1 | N11: H3 y H4 | O11: Metropolitana de Santiago | P11: Huechuraba | Q11: Zonal | R11: 16/01/2023 17:52:20 | S11: 07/2024
A12: 1135 | B12: DC Padre Hurtado - Fase 2 | C12: 3409 | D12: Electrica Padre Hurtado SpA | E12: SAC | F12: Rechazada | G12: 21 de abril de 2022 11:37:33 | H12: 50 | I12: Consumo | J12: 30 de marzo de 2024 00:00:00 | K12: S/E Padre Hurtado 110 kV | L12: 110 | M12: Barra Principal | N12: H2 | O12: Metropolitana de Santiago | P12: Padre Hurtado | Q12: Zonal
A13: 1182 | B13: DC Padre Hurtado - Fase 3 | C13: 3491 | D13: Electrica Padre Hurtado SpA | E13: SAC | F13: Rechazada | G13: 9 de junio de 2022 17:51:57 | H13: 60 | I13: Consumo | J13: 30 de junio de 2024 00:00:00 | K13: S/E Santa Marta 110 kV | L13: 110 | M13: Barra Principal | N13: H3 | O13: Metropolitana de Santiago | P13: Padre Hurtado | Q13: Zonal
A14: 1286 | B14: DC Huechuraba - Fase 1 v01 | C14: 3685 | D14: Electrica Huechuraba SpA | E14: SAC | F14: Proyecto autorizado para declararse en construcción | G14: 22 de septiembre de 2022 16:32:34 | H14: 10 | I14: Consumo | J14: Fecha inválida | K14: S/E Recoleta 12 kV | L14: 12 | M14: Barra Principal N°3 12,5 kV | N14: E21 y E22 | O14: Metropolitana de Santiago | P14: Huechuraba | Q14: Zonal | R14: 22/06/2023 14:24:37 | S14: 09/2023 | T14: 09/2025
A15: 1516 | B15: Datacenter Pisco | C15: 4167 | D15: Microsoft Datacenter Chile SA | E15: SAC | F15: Elaboración Informe de Autorización de Conexión Preliminar | G15: 8 de junio de 2023 10:24:41 | H15: 50 | I15: Consumo | J15: 5 de julio de 2025 00:00:00 | K15: S/E Chicureo 220 kV | L15: 220 | M15: Barra principal 1 | N15: J3 | O15: Metropolitana de Santiago | P15: Colina | Q15: Zonal
A16: 2010 | B16: DC Curauma Fase 2 | C16: 4948 | D16: Scala Chile Data Centers SpA | E16: SAC | F16: Periodo de presentación de discrepancias | G16: 23 de mayo de 2024 15:20:42 | H16: 50 | I16: Consumo | J16: 15 de febrero de 2027 00:00:00 | K16: S/E Curauma 110 kV | L16: 110 | M16: Barra Principal, Paños H3 y H6 | N16: H3 y H6 | O16: Valparaiso | P16: Valparaíso | Q16: Zonal
A17: 2044 | B17: Datacenter Pisco 2 | C17: 5044 | D17: Microsoft Datacenter Chile SA | E17: SAC | F17: Proyecto autorizado para declararse en construcción | G17: 28 de junio de 2024 10:22:51 | H17: 50 | I17: Consumo | J17: 31 de julio de 2026 00:00:00 | K17: S/E Chicureo 220 kV | L17: 220 | M17: Barra 2 | N17: J4 | O17: Metropolitana de Santiago | P17: Colina | Q17: Zonal | R17: 14/04/2025 11:28:47 | S17: 10/2025
A18: 2179 | B18: Solution 2 | C18: 5260 | D18: ENSOLUTION SPA | E18: SAC | F18: Proyecto autorizado para declararse en construcción | G18: 15 de octubre de 2024 09:49:25 | H18: 450 | I18: Consumo | J18: 29 de diciembre de 2028 00:00:00 | K18: S/E Alto Jahuel 500 kV | L18: 500 | M18: Doble Barra + Barra Transferencia | N18: K7 | O18: Metropolitana de Santiago | P18: Buin | Q18: Nacional | R18: 04/07/2025 12:14:14 | S18: 06/2027
A19: 2325 | B19: Datacenter Condor 2 | C19: 5433 | D19: Microsoft Datacenter Chile SA | E19: SAC | F19: Observaciones a Informe de Autorización de Conexión Preliminar | G19: 19 de diciembre de 2024 17:00:01 | H19: 25 | I19: Consumo | J19: 17 de enero de 2027 00:00:00 | K19: SE Chacabuco 110kV | L19: 110 | M19: Doble barra | N19: H3, H4 | O19: Metropolitana de Santiago | P19: Quilicura | Q19: Zonal
A20: 2377 | B20: DC Valparaiso 1 | C20: 5497 | D20: FR DATA SpA | E20: SAC | F20: Detenida a la espera de definición de ingeniería de la obra | G20: 29 de enero de 2025 16:12:07 | H20: 200 | I20: Consumo | J20: 1 de abril de 2028 00:00:00 | K20: SE La Polvora | L20: 220 | M20: Barra principal N°2 | N20: J15 | O20: Valparaiso | P20: Valparaíso | Q20: Nacional
A21: 2378 | B21: DC Valparaiso 2 | C21: 5498 | D21: FR DATA SpA | E21: SAC | F21: Detenida a la espera de definición de ingeniería de la obra | G21: 29 de enero de 2025 16:19:36 | H21: 100 | I21: Consumo | J21: 1 de abril de 2028 00:00:00 | K21: SE La Polvora | L21: 220 | M21: Barra principal N°2 | N21: J18 | O21: Valparaiso | P21: Valparaíso | Q21: Nacional
A22: 2443 | B22: DC Alto Jahuel | C22: 5570 | D22: FR DATA SpA | E22: SAC | F22: Evaluación de antecedentes y/o requerimientos | G22: 10 de febrero de 2025 10:25:47 | H22: 200 | I22: Consumo | J22: 1 de abril de 2028 00:00:00 | K22: S/E Maipo 220kV | L22: 220 | M22: Barra GIS 1 y 2 | N22: J3 | O22: Metropolitana de Santiago | P22: Buin | Q22: Nacional
A23: 2515 | B23: Campo de Datos Lampa | C23: 5768 | D23: CI GMF II Patache ProjectCo SpA | E23: SAC | F23: Desarrollo de estudios y/o antecedentes | G23: 7 de mayo de 2025 17:29:33 | H23: 0 | I23: Consumo | J23: 31 de diciembre de 2029 00:00:00 | K23: Nueva Lampa 220kV | L23: 220 | M23: Interruptor y medio | N23: J18 y J21 | O23: Metropolitana de Santiago | P23: Lampa | Q23: Nacional

Sheet DC SEA  2026
Z1: MANO DE OBRA
K2: Grupo electrógeno | M2: total principal | P2: total respaldo | W2: total chiller | X2: total general GE PyR KW
A3: Nombre del Proyecto | B3: WEB | C3: Región | D3: Comuna | E3: Titular | F3: Inversión (MMU$) | G3: Estado del Proyecto | H3: Días DIA | I3: Fecha Calificación | J3: Empresa Consultora | K3: GE Salas (Principal) | L3: P Generada (KW) | M3: Total Generado KW | N3: GE Oficinas (Respaldo) | O3: P Generada (KW)2 | P3: Total Generado KW2 | Q3: Cantidad Diesel /L | R3: Cantidad Diesel /kg | S3: Ratio L/kg | T3: Vida util Años DC | U3: Cantidad Chillers | V3: Consumo (KW)3 | W3: Total consumo Chillers KW | X3: Total general GE PyR KW | Y3: Principal IT /1.5 | Z3: Promedio construcción | AA3: Máximo P construcción | AB3: Promedio Operación | AC3: Máximo P Operación | AD3: Promedio Cierre | AE3: Máximo P Cierre | AF3: MO Contrucción Promedio | AG3: MO Contrucción Máximo | AH3: MO Operación Promedio | AI3: MO Operación Máximo | AJ3: MO Cierre Promedio | AK3: MO Cierre Máximo | AL3: Latitud | AM3: Longitud | AN3: Superficie útil m2 | AO3: Superficie Bruta m2 | AP3: Empresa | AQ3: Proyectos | AR3: CAPEX (MMUSD)
A4: Centro de Almacenamiento de Datos Puente Alto | B4: Ver | C4: Metropolitana | D4: Puente Alto | E4: Inmobiliaria STPA SPA | F4: 0 | G4: Pendiente | H4: =+(Tabla35[[#This Row],[Fecha Calificación]]-TODAY())*-1 -> 31 | I4: 46265 | J4: Inmobiliaria STPA SPA | K4: 44 | L4: 2200 | M4: =Tabla35[[#This Row],[P Generada (KW)]]*Tabla35[[#This Row],[GE Salas (Principal)]] -> 96800 | N4: 2 | O4: 2200 | P4: =Tabla35[[#This Row],[P Generada (KW)2]]*Tabla35[[#This Row],[GE Oficinas (Respaldo)]] -> 4400 | Q4: 900450 | R4: 756000 | S4: =+Tabla35[[#This Row],[Cantidad Diesel /kg]]/Tabla35[[#This Row],[Cantidad Diesel /L]] -> 0.83958021 | U4: 120 | V4: 1600 | W4: =Tabla35[[#This Row],[Consumo (KW)3]]*Tabla35[[#This Row],[Cantidad Chillers]] -> 192000 | X4: =Tabla35[[#This Row],[Total consumo Chillers KW]]+Tabla35[[#This Row],[Total Generado KW2]]+Tabla35[[#This Row],[Total Generado KW]] -> 293200 | Y4: =Tabla35[[#This Row],[Total Generado KW]]/1.5 -> 64533.333 | Z4: =+Tabla35[[#This Row],[MO Contrucción Promedio]]/Tabla35[[#This Row],[Total Generado KW]] -> 0
A5: Centro de Almacenamiento de Datos San Antonio | B5: Ver | C5: Valparaíso | D5: San Antonio | E5: Nodo Pacífico SpA | F5: 262 | G5: Pendiente | H5: =+(Tabla35[[#This Row],[Fecha Calificación]]-TODAY())*-1 -> 3 | I5: 46293 | J5: Sustentable | K5: 32 | L5: 2578 | M5: =+Tabla35[[#This Row],[P Generada (KW)]]*Tabla35[[#This Row],[GE Salas (Principal)]] -> 82496 | N5: 2 | O5: =+Tabla35[[#This Row],[GE Oficinas (Respaldo)]]*Tabla35[[#This Row],[P Generada (KW)]] -> 5156 | P5: =Tabla35[[#This Row],[P Generada (KW)2]]*Tabla35[[#This Row],[GE Oficinas (Respaldo)]] -> 10312 | Q5: =+Tabla35[[#This Row],[Cantidad Diesel /kg]]/Tabla35[[#This Row],[Ratio L/kg]] -> 990000 | R5: 841500 | S5: 0.85 | W5: =Tabla35[[#This Row],[Consumo (KW)3]]*Tabla35[[#This Row],[Cantidad Chillers]] -> 0 | X5: =Tabla35[[#This Row],[Total consumo Chillers KW]]+Tabla35[[#This Row],[Total Generado KW2]]+Tabla35[[#This Row],[Total Generado KW]] -> 92808 | Y5: =Tabla35[[#This Row],[Total Generado KW]]/1.5 -> 54997.333 | Z5: =+Tabla35[[#This Row],[MO Contrucción Promedio]]/Tabla35[[#This Row],[Total Generado KW]] -> 0
A6: Data Center Polpaico Campus Norte | B6: Ver | C6: Metropolitana | D6: Til-til | E6: GR Culle SpA | F6: 25 | G6: Pendiente | H6: =+(Tabla35[[#This Row],[Fecha Calificación]]-TODAY())*-1 -> 16 | I6: 46280 | J6: Grenergy | K6: 60 | L6: 2800 | M6: =Tabla35[[#This Row],[P Generada (KW)]]*Tabla35[[#This Row],[GE Salas (Principal)]] -> 168000 | P6: =Tabla35[[#This Row],[P Generada (KW)2]]*Tabla35[[#This Row],[GE Oficinas (Respaldo)]] -> 0 | R6: <1000 | S6: =+Tabla35[[#This Row],[Cantidad Diesel /kg]]/Tabla35[[#This Row],[Cantidad Diesel /L]] -> #VALUE! | W6: =Tabla35[[#This Row],[Consumo (KW)3]]*Tabla35[[#This Row],[Cantidad Chillers]] -> 0 | X6: =Tabla35[[#This Row],[Total consumo Chillers KW]]+Tabla35[[#This Row],[Total Generado KW2]]+Tabla35[[#This Row],[Total Generado KW]] -> 168000 | Y6: =Tabla35[[#This Row],[Total Generado KW]]/1.5 -> 112000 | Z6: =+Tabla35[[#This Row],[MO Contrucción Promedio]]/Tabla35[[#This Row],[Total Generado KW]] -> 0
A7: Data Center Lo Aguirre | B7: =HYPERLINK("https://infofirma.sea.gob.cl/DocumentosSEA/MostrarDocumento?docId=2026/09/26/40d9-b957-46d4-b27d-350f082b2f28","Ver") -> Ver | C7: Metropolitana | D7: Pudahuel | E7: Lader Energy Chile SpA | F7: 25 | G7: Pendiente | H7: =+(Tabla35[[#This Row],[Fecha Calificación]]-TODAY())*-1 -> 68 | I7: 46228 | J7: Lader Energy Chile SpA | K7: 60 | L7: 2800 | M7: =Tabla35[[#This Row],[P Generada (KW)]]*Tabla35[[#This Row],[GE Salas (Principal)]] -> 168000 | P7: =Tabla35[[#This Row],[P Generada (KW)2]]*Tabla35[[#This Row],[GE Oficinas (Respaldo)]] -> 0 | Q7: 1164705 | R7: 990000 | S7: =+Tabla35[[#This Row],[Cantidad Diesel /kg]]/Tabla35[[#This Row],[Cantidad Diesel /L]] -> 0.85000064 | T7: 30 | W7: =Tabla35[[#This Row],[Consumo (KW)3]]*Tabla35[[#This Row],[Cantidad Chillers]] -> 0 | X7: =Tabla35[[#This Row],[Total consumo Chillers KW]]+Tabla35[[#This Row],[Total Generado KW2]]+Tabla35[[#This Row],[Total Generado KW]] -> 168000 | Y7: =Tabla35[[#This Row],[Total Generado KW]]/1.5 -> 112000 | Z7: =+Tabla35[[#This Row],[MO Contrucción Promedio]]/Tabla35[[#This Row],[Total Generado KW]] -> 0.0020833333 | AA7: =+Tabla35[[#This Row],[MO Contrucción Máximo]]/Tabla35[[#This Row],[Total Generado KW]] -> 0.0041666667 | AB7: =+Tabla35[[#This Row],[MO Operación Promedio]]/Tabla35[[#This Row],[Total Generado KW]] -> 0.00089285714 | AC7: =+Tabla35[[#This Row],[MO Operación Máximo]]/Tabla35[[#This Row],[Total Generado KW]] -> 0.0017857143 | AD7: =+Tabla35[[#This Row],[MO Cierre Promedio]]/Tabla35[[#This Row],[Total Generado KW]] -> 0.0020833333 | AE7: =+Tabla35[[#This Row],[MO Cierre Máximo]]/Tabla35[[#This Row],[Total Generado KW]] -> 0.0041666667 | AF7: 350 | AG7: 700 | AH7: 150 | AI7: 300 | AJ7: 350 | AK7: 700 | AL7: -70907931 | AM7: -33450639 | AN7: 83568 | AO7: 171373
A8: Data Center La Polvora | B8: =HYPERLINK("https://infofirma.sea.gob.cl/DocumentosSEA/MostrarDocumento?docId=2026/07/30/4984-cbee-46bd-816a-cfd384a6bbbf","Ver") -> Ver | C8: Valparaíso | D8: Valparaíso | E8: DCI LA POLVORA SpA | F8: 25 | G8: Pendiente | H8: =+(Tabla35[[#This Row],[Fecha Calificación]]-TODAY())*-1 -> 70 | I8: 46226 | J8: DCI Partners | K8: 54 | L8: 2800 | M8: =Tabla35[[#This Row],[P Generada (KW)]]*Tabla35[[#This Row],[GE Salas (Principal)]] -> 151200 | P8: =Tabla35[[#This Row],[P Generada (KW)2]]*Tabla35[[#This Row],[GE Oficinas (Respaldo)]] -> 0 | Q8: 1164705 | R8: 990000 | S8: =+Tabla35[[#This Row],[Cantidad Diesel /kg]]/Tabla35[[#This Row],[Cantidad Diesel /L]] -> 0.85000064 | W8: =Tabla35[[#This Row],[Consumo (KW)3]]*Tabla35[[#This Row],[Cantidad Chillers]] -> 0 | X8: =Tabla35[[#This Row],[Total consumo Chillers KW]]+Tabla35[[#This Row],[Total Generado KW2]]+Tabla35[[#This Row],[Total Generado KW]] -> 151200 | Y8: =Tabla35[[#This Row],[Total Generado KW]]/1.5 -> 100800 | Z8: =+Tabla35[[#This Row],[MO Contrucción Promedio]]/Tabla35[[#This Row],[Total Generado KW]] -> 0 | AA8: =+Tabla35[[#This Row],[MO Contrucción Máximo]]/Tabla35[[#This Row],[Total Generado KW]] -> 0.0031746032 | AB8: =+Tabla35[[#This Row],[MO Operación Promedio]]/Tabla35[[#This Row],[Total Generado KW]] -> 0 | AC8: =+Tabla35[[#This Row],[MO Operación Máximo]]/Tabla35[[#This Row],[Total Generado KW]] -> 0.0015873016 | AD8: =+Tabla35[[#This Row],[MO Cierre Promedio]]/Tabla35[[#This Row],[Total Generado KW]] -> 0 | AE8: =+Tabla35[[#This Row],[MO Cierre Máximo]]/Tabla35[[#This Row],[Total Generado KW]] -> 0 | AG8: 480 | AI8: 240 | AL8: -71619954514165 | AM8: -33086077367795 | AN8: 52000 | AO8: 66649
A9: Datacenter Terranova Alto Jahuel | B9: =HYPERLINK("https://infofirma.sea.gob.cl/DocumentosSEA/MostrarDocumento?docId=2026/05/05/aaf0-5d7c-4f7a-9163-f58684ca2a4a","Ver") -> Ver | C9: Metropolitana | D9: Buin | E9: DC Terranova | F9: 25 | G9: Pendiente | H9: =+(Tabla35[[#This Row],[Fecha Calificación]]-TODAY())*-1 -> 149 | I9: 46147 | J9: Sustentable | K9: 54 | L9: 2250 | M9: =Tabla35[[#This Row],[P Generada (KW)]]*Tabla35[[#This Row],[GE Salas (Principal)]] -> 121500 | N9: 2 | O9: 1100 | P9: =Tabla35[[#This Row],[P Generada (KW)2]]*Tabla35[[#This Row],[GE Oficinas (Respaldo)]] -> 2200 | Q9: 1164705 | R9: 990000 | S9: =+Tabla35[[#This Row],[Cantidad Diesel /kg]]/Tabla35[[#This Row],[Cantidad Diesel /L]] -> 0.85000064 | T9: Indefinida | W9: =Tabla35[[#This Row],[Consumo (KW)3]]*Tabla35[[#This Row],[Cantidad Chillers]] -> 0 | X9: =Tabla35[[#This Row],[Total consumo Chillers KW]]+Tabla35[[#This Row],[Total Generado KW2]]+Tabla35[[#This Row],[Total Generado KW]] -> 123700 | Y9: =Tabla35[[#This Row],[Total Generado KW]]/1.5 -> 81000 | Z9: =+Tabla35[[#This Row],[MO Contrucción Promedio]]/Tabla35[[#This Row],[Total Generado KW]] -> 0 | AA9: =+Tabla35[[#This Row],[MO Contrucción Máximo]]/Tabla35[[#This Row],[Total Generado KW]] -> 0.0032921811 | AB9: =+Tabla35[[#This Row],[MO Operación Promedio]]/Tabla35[[#This Row],[Total Generado KW]] -> 0 | AC9: =+Tabla35[[#This Row],[MO Operación Máximo]]/Tabla35[[#This Row],[Total Generado KW]] -> 0.002526749 | AD9: =+Tabla35[[#This Row],[MO Cierre Promedio]]/Tabla35[[#This Row],[Total Generado KW]] -> 0 | AE9: =+Tabla35[[#This Row],[MO Cierre Máximo]]/Tabla35[[#This Row],[Total Generado KW]] -> 0 | AG9: 400 | AI9: 307 | AL9: -33.7186 | AM9: -70.6912 | AN9: 32141.842 | AO9: 56200
A10: Campo de Datos Lampa | B10: =HYPERLINK("https://infofirma.sea.gob.cl/DocumentosSEA/MostrarDocumento?docId=2026/07/13/14d0-c32d-4f7a-9c8d-5ccb210b429f","Ver") -> Ver | C10: Metropolitana | D10: Lampa | E10: CI GMF II Chile DevCo I SpA | F10: 850 | G10: Pendiente | H10: =+(Tabla35[[#This Row],[Fecha Calificación]]-TODAY())*-1 -> 80 | I10: 46216 | J10: GIZA Ingeniería | K10: 45 | L10: 2500 | M10: =Tabla35[[#This Row],[P Generada (KW)]]*Tabla35[[#This Row],[GE Salas (Principal)]] -> 112500 | N10: 1 | O10: 1020 | P10: =Tabla35[[#This Row],[P Generada (KW)2]]*Tabla35[[#This Row],[GE Oficinas (Respaldo)]] -> 1020 | Q10: 601647 | R10: 511400 | S10: =+Tabla35[[#This Row],[Cantidad Diesel /kg]]/Tabla35[[#This Row],[Cantidad Diesel /L]] -> 0.85000008 | T10: Indefinida | U10: 90 | W10: =Tabla35[[#This Row],[Consumo (KW)3]]*Tabla35[[#This Row],[Cantidad Chillers]] -> 0 | X10: =Tabla35[[#This Row],[Total consumo Chillers KW]]+Tabla35[[#This Row],[Total Generado KW2]]+Tabla35[[#This Row],[Total Generado KW]] -> 113520 | Y10: =Tabla35[[#This Row],[Total Generado KW]]/1.5 -> 75000 | Z10: =+Tabla35[[#This Row],[MO Contrucción Promedio]]/Tabla35[[#This Row],[Total Generado KW]] -> 0 | AA10: =+Tabla35[[#This Row],[MO Contrucción Máximo]]/Tabla35[[#This Row],[Total Generado KW]] -> 0.0026666667 | AB10: =+Tabla35[[#This Row],[MO Operación Promedio]]/Tabla35[[#This Row],[Total Generado KW]] -> 0 | AC10: =+Tabla35[[#This Row],[MO Operación Máximo]]/Tabla35[[#This Row],[Total Generado KW]] -> 0.0013333333 | AD10: =+Tabla35[[#This Row],[MO Cierre Promedio]]/Tabla35[[#This Row],[Total Generado KW]] -> 0 | AE10: =+Tabla35[[#This Row],[MO Cierre Máximo]]/Tabla35[[#This Row],[Total Generado KW]] -> 0 | AG10: 300 | AI10: 150 | AL10: -7076770157877 | AM10: -33317910875209 | AN10: 39397.71 | AO10: 219476
A11: Data Center Alto Jahuel Campus Sur | B11: =HYPERLINK("https://infofirma.sea.gob.cl/DocumentosSEA/MostrarDocumento?docId=2026/05/29/d544-ae11-47d8-8e57-90e569bf78e3","Ver") -> Ver | C11: Metropolitana | D11: Buin | E11: GR Huiña SpA | F11: 20 | G11: Pendiente | H11: =+(Tabla35[[#This Row],[Fecha Calificación]]-TODAY())*-1 -> 125 | I11: 46171 | J11: Grenergy | K11: 48 | L11: 2800 | M11: =Tabla35[[#This Row],[P Generada (KW)]]*Tabla35[[#This Row],[GE Salas (Principal)]] -> 134400 | P11: =Tabla35[[#This Row],[P Generada (KW)2]]*Tabla35[[#This Row],[GE Oficinas (Respaldo)]] -> 0 | Q11: 1170588 | R11: 995000 | S11: =+Tabla35[[#This Row],[Cantidad Diesel /kg]]/Tabla35[[#This Row],[Cantidad Diesel /L]] -> 0.85000017 | T11: 30 | W11: =Tabla35[[#This Row],[Consumo (KW)3]]*Tabla35[[#This Row],[Cantidad Chillers]] -> 0 | X11: =Tabla35[[#This Row],[Total consumo Chillers KW]]+Tabla35[[#This Row],[Total Generado KW2]]+Tabla35[[#This Row],[Total Generado KW]] -> 134400 | Y11: =Tabla35[[#This Row],[Total Generado KW]]/1.5 -> 89600 | Z11: =+Tabla35[[#This Row],[MO Contrucción Promedio]]/Tabla35[[#This Row],[Total Generado KW]] -> 0 | AA11: =+Tabla35[[#This Row],[MO Contrucción Máximo]]/Tabla35[[#This Row],[Total Generado KW]] -> 0.0016369048 | AB11: =+Tabla35[[#This Row],[MO Operación Promedio]]/Tabla35[[#This Row],[Total Generado KW]] -> 0 | AC11: =+Tabla35[[#This Row],[MO Operación Máximo]]/Tabla35[[#This Row],[Total Generado KW]] -> 0.00081845238 | AD11: =+Tabla35[[#This Row],[MO Cierre Promedio]]/Tabla35[[#This Row],[Total Generado KW]] -> 0 | AE11: =+Tabla35[[#This Row],[MO Cierre Máximo]]/Tabla35[[#This Row],[Total Generado KW]] -> 0 | AG11: 220 | AI11: 110 | AL11: -33.707188 | AM11: -70.697045 | AN11: 58500 | AO11: 85275.48
A12: Datacenter ST5 | B12: Ver | C12: Metropolitana | D12: Pudahuel | E12: Equinix | F12: 130 | G12: Aprobado | H12: 367.72455 | I12: 45768.667 | J12: GIZA Ingeniería | K12: 16 | L12: 2800 | M12: =Tabla35[[#This Row],[P Generada (KW)]]*Tabla35[[#This Row],[GE Salas (Principal)]] -> 44800 | N12: 1 | O12: 720 | P12: =Tabla35[[#This Row],[P Generada (KW)2]]*Tabla35[[#This Row],[GE Oficinas (Respaldo)]] -> 720 | Q12: 337500 | R12: 286875 | S12: =+Tabla35[[#This Row],[Cantidad Diesel /kg]]/Tabla35[[#This Row],[Cantidad Diesel /L]] -> 0.85 | T12: 33,5 | U12: 28 | V12: 1420 | W12: =Tabla35[[#This Row],[Consumo (KW)3]]*Tabla35[[#This Row],[Cantidad Chillers]] -> 39760 | X12: =Tabla35[[#This Row],[Total Generado KW]]+Tabla35[[#This Row],[Total Generado KW2]] -> 45520 | Y12: =Tabla35[[#This Row],[Total Generado KW]]/1.5 -> 29866.667 | Z12: =+Tabla35[[#This Row],[MO Contrucción Promedio]]/Tabla35[[#This Row],[Total Generado KW]] -> 0.0020089286 | AA12: =+Tabla35[[#This Row],[MO Contrucción Máximo]]/Tabla35[[#This Row],[Total Generado KW]] -> 0.0040178571 | AB12: =+Tabla35[[#This Row],[MO Operación Promedio]]/Tabla35[[#This Row],[Total Generado KW]] -> 0.00089285714 | AC12: =+Tabla35[[#This Row],[MO Operación Máximo]]/Tabla35[[#This Row],[Total Generado KW]] -> 0.0013392857 | AD12: =+Tabla35[[#This Row],[MO Cierre Promedio]]/Tabla35[[#This Row],[Total Generado KW]] -> 0.00044642857 | AE12: =+Tabla35[[#This Row],[MO Cierre Máximo]]/Tabla35[[#This Row],[Total Generado KW]] -> 0.00089285714 | AF12: 90 | AG12: 180 | AH12: 40 | AI12: 60 | AJ12: 20 | AK12: 40 | AL12: -33.438927 | AM12: -70.785885 | AN12: 24418 | AO12: 42409 | AP12: Equinix | AQ12: =+COUNTIFS(Tabla35[Titular],AP12,Tabla35[Estado del Proyecto],"Aprobado") -> 2 | AR12: =+SUMIFS(Tabla35[Inversión (MMU$)],Tabla35[Titular],AP12,Tabla35[Estado del Proyecto],"Aprobado") -> 174
A13: Ampliación Data Center Campus Scala Huechuraba | B13: Ver | C13: Metropolitana | D13: Huechuraba | E13: SCALA | F13: 145.2 | G13: Aprobado | H13: 167.82309 | I13: 45705.625 | J13: IT Ambiental | K13: 16 | L13: 2800 | M13: 33925 | N13: 3 | O13: 616 | P13: =Tabla35[[#This Row],[P Generada (KW)2]]*Tabla35[[#This Row],[GE Oficinas (Respaldo)]] -> 1848 | Q13: 300000 | R13: 255000 | S13: =+Tabla35[[#This Row],[Cantidad Diesel /kg]]/Tabla35[[#This Row],[Cantidad Diesel /L]] -> 0.85 | T13: Indefinida | U13: 14 | V13: 1560 | W13: =Tabla35[[#This Row],[Consumo (KW)3]]*Tabla35[[#This Row],[Cantidad Chillers]] -> 21840 | X13: =Tabla35[[#This Row],[Total Generado KW]]+Tabla35[[#This Row],[Total Generado KW2]] -> 35773 | Y13: =Tabla35[[#This Row],[Total Generado KW]]/1.5 -> 22616.667 | Z13: =+Tabla35[[#This Row],[MO Contrucción Promedio]]/Tabla35[[#This Row],[Total Generado KW]] -> 0.0044215181 | AA13: =+Tabla35[[#This Row],[MO Contrucción Máximo]]/Tabla35[[#This Row],[Total Generado KW]] -> 0.0088430361 | AB13: =+Tabla35[[#This Row],[MO Operación Promedio]]/Tabla35[[#This Row],[Total Generado KW]] -> 0.0026529108 | AC13: =+Tabla35[[#This Row],[MO Operación Máximo]]/Tabla35[[#This Row],[Total Generado KW]] -> 0.0029476787 | AD13: =+Tabla35[[#This Row],[MO Cierre Promedio]]/Tabla35[[#This Row],[Total Generado KW]] -> 0.0013264554 | AE13: =+Tabla35[[#This Row],[MO Cierre Máximo]]/Tabla35[[#This Row],[Total Generado KW]] -> 0.0014738394 | AF13: 150 | AG13: 300 | AH13: 90 | AI13: 100 | AJ13: 45 | AK13: 50 | AL13: -33.366358 | AM13: -70.673941 | AN13: 30197.78 | AO13: 38778 | AP13: SCALA | AQ13: =+COUNTIFS(Tabla35[Titular],AP13,Tabla35[Estado del Proyecto],"Aprobado") -> 4 | AR13: =+SUMIFS(Tabla35[Inversión (MMU$)],Tabla35[Titular],AP13,Tabla35[Estado del Proyecto],"Aprobado") -> 873.2
A14: Ampliación Data Center Campus Scala Huechuraba | B14: Ver | C14: Valparaíso | D14: Valparaíso | E14: SCALA | F14: 290 | G14: Aprobado | H14: 382.0183 | I14: 45636.625 | J14: IT Ambiental | K14: 30 | L14: 2750 | M14: =Tabla35[[#This Row],[P Generada (KW)]]*Tabla35[[#This Row],[GE Salas (Principal)]] -> 82500 | N14: 5 | O14: 400 | P14: =Tabla35[[#This Row],[P Generada (KW)2]]*Tabla35[[#This Row],[GE Oficinas (Respaldo)]] -> 2000 | Q14: 1090000 | R14: 926500 | S14: =+Tabla35[[#This Row],[Cantidad Diesel /kg]]/Tabla35[[#This Row],[Cantidad Diesel /L]] -> 0.85 | T14: Indefinida | U14: 25 | V14: 1550 | W14: =Tabla35[[#This Row],[Consumo (KW)3]]*Tabla35[[#This Row],[Cantidad Chillers]] -> 38750 | X14: =Tabla35[[#This Row],[Total Generado KW]]+Tabla35[[#This Row],[Total Generado KW2]] -> 84500 | Y14: =Tabla35[[#This Row],[Total Generado KW]]/1.5 -> 55000 | Z14: =+Tabla35[[#This Row],[MO Contrucción Promedio]]/Tabla35[[#This Row],[Total Generado KW]] -> 0.0043636364 | AA14: =+Tabla35[[#This Row],[MO Contrucción Máximo]]/Tabla35[[#This Row],[Total Generado KW]] -> 0.0072727273 | AB14: =+Tabla35[[#This Row],[MO Operación Promedio]]/Tabla35[[#This Row],[Total Generado KW]] -> 0.00063030303 | AC14: =+Tabla35[[#This Row],[MO Operación Máximo]]/Tabla35[[#This Row],[Total Generado KW]] -> 0.0012363636 | AD14: =+Tabla35[[#This Row],[MO Cierre Promedio]]/Tabla35[[#This Row],[Total Generado KW]] -> 0.00024242424 | AE14: =+Tabla35[[#This Row],[MO Cierre Máximo]]/Tabla35[[#This Row],[Total Generado KW]] -> 0.00048484848 | AF14: 360 | AG14: 600 | AH14: 52 | AI14: 102 | AJ14: 20 | AK14: 40 | AL14: -33.13749 | AM14: -71.55948 | AN14: 33302 | AO14: 82448 | AP14: EdgeConnex | AQ14: =+COUNTIFS(Tabla35[Titular],AP14,Tabla35[Estado del Proyecto],"Aprobado") -> 3 | AR14: =+SUMIFS(Tabla35[Inversión (MMU$)],Tabla35[Titular],AP14,Tabla35[Estado del Proyecto],"Aprobado") -> 213
A15: Data Center SCL04 | B15: Ver | C15: Metropolitana | D15: Colina | E15: EdgeConnex | F15: 40 | G15: Aprobado | H15: 307.92259 | I15: 45468.667 | J15: GIZA Ingeniería | K15: 18 | L15: 3000 | M15: =Tabla35[[#This Row],[P Generada (KW)]]*Tabla35[[#This Row],[GE Salas (Principal)]] -> 54000 | N15: 3 | O15: 3000 | P15: =Tabla35[[#This Row],[P Generada (KW)2]]*Tabla35[[#This Row],[GE Oficinas (Respaldo)]] -> 9000 | Q15: 933555 | R15: 1098300 | S15: =+Tabla35[[#This Row],[Cantidad Diesel /kg]]/Tabla35[[#This Row],[Cantidad Diesel /L]] -> 1.1764706 | T15: 27 | U15: 42 | V15: No se especifica | W15: 0 | X15: =Tabla35[[#This Row],[Total Generado KW]]+Tabla35[[#This Row],[Total Generado KW2]] -> 63000 | Y15: =Tabla35[[#This Row],[Total Generado KW]]/1.5 -> 36000 | Z15: =+Tabla35[[#This Row],[MO Contrucción Promedio]]/Tabla35[[#This Row],[Total Generado KW]] -> 0.002 | AA15: =+Tabla35[[#This Row],[MO Contrucción Máximo]]/Tabla35[[#This Row],[Total Generado KW]] -> 0.0033333333 | AB15: =+Tabla35[[#This Row],[MO Operación Promedio]]/Tabla35[[#This Row],[Total Generado KW]] -> 0.0013888889 | AC15: =+Tabla35[[#This Row],[MO Operación Máximo]]/Tabla35[[#This Row],[Total Generado KW]] -> 0.0027777778 | AD15: =+Tabla35[[#This Row],[MO Cierre Promedio]]/Tabla35[[#This Row],[Total Generado KW]] -> 0.00037037037 | AE15: =+Tabla35[[#This Row],[MO Cierre Máximo]]/Tabla35[[#This Row],[Total Generado KW]] -> 0.00074074074 | AF15: 108 | AG15: 180 | AH15: 75 | AI15: 150 | AJ15: 20 | AK15: 40 | AL15: -33.297771 | AM15: -70.705801 | AN15: 34200 | AO15: 65000 | AP15: Cirion | AQ15: =+COUNTIFS(Tabla35[Titular],AP15,Tabla35[Estado del Proyecto],"Aprobado") -> 1 | AR15: =+SUMIFS(Tabla35[Inversión (MMU$)],Tabla35[Titular],AP15,Tabla35[Estado del Proyecto],"Aprobado") -> 120
A16: Data Center Cirion | B16: Ver | C16: Metropolitana | D16: Quilicura | E16: Cirion | F16: 120 | G16: Aprobado | H16: 236.83172 | I16: 45313.625 | J16: GIZA Ingeniería | K16: 16 | L16: 1850 | M16: =Tabla35[[#This Row],[P Generada (KW)]]*Tabla35[[#This Row],[GE Salas (Principal)]] -> 29600 | N16: 0 | O16: 0 | P16: =Tabla35[[#This Row],[P Generada (KW)2]]*Tabla35[[#This Row],[GE Oficinas (Respaldo)]] -> 0 | Q16: 400000 | R16: 340000 | S16: =+Tabla35[[#This Row],[Cantidad Diesel /kg]]/Tabla35[[#This Row],[Cantidad Diesel /L]] -> 0.85 | T16: 27 | U16: No se especifica | V16: No se especifica | X16: =Tabla35[[#This Row],[Total Generado KW]]+Tabla35[[#This Row],[Total Generado KW2]] -> 29600 | Y16: =Tabla35[[#This Row],[Total Generado KW]]/1.5 -> 19733.333 | Z16: =+Tabla35[[#This Row],[MO Contrucción Promedio]]/Tabla35[[#This Row],[Total Generado KW]] -> 0.0036486486 | AA16: =+Tabla35[[#This Row],[MO Contrucción Máximo]]/Tabla35[[#This Row],[Total Generado KW]] -> 0.0060810811 | AB16: =+Tabla35[[#This Row],[MO Operación Promedio]]/Tabla35[[#This Row],[Total Generado KW]] -> 0.00067567568 | AC16: =+Tabla35[[#This Row],[MO Operación Máximo]]/Tabla35[[#This Row],[Total Generado KW]] -> 0.0013513514 | AD16: =+Tabla35[[#This Row],[MO Cierre Promedio]]/Tabla35[[#This Row],[Total Generado KW]] -> 0.00067567568 | AE16: =+Tabla35[[#This Row],[MO Cierre Máximo]]/Tabla35[[#This Row],[Total Generado KW]] -> 0.0013513514 | AF16: 108 | AG16: 180 | AH16: 20 | AI16: 40 | AJ16: 20 | AK16: 40 | AL16: -33.356811 | AM16: -70.69955 | AP16: Amazon | AQ16: =+COUNTIFS(Tabla35[Titular],AP16,Tabla35[Estado del Proyecto],"Aprobado") -> 2 | AR16: =+SUMIFS(Tabla35[Inversión (MMU$)],Tabla35[Titular],AP16,Tabla35[Estado del Proyecto],"Aprobado") -> 410
A17: Centro de Almacenamiento de Datos Huechuraba | B17: Ver | C17: Metropolitana | D17: Huechuraba | E17: Amazon | F17: 205 | G17: Aprobado | H17: 527.10205 | I17: 45471.667 | J17: ORBE Consultores | K17: 20 | L17: 2800 | M17: =Tabla35[[#This Row],[P Generada (KW)]]*Tabla35[[#This Row],[GE Salas (Principal)]] -> 56000 | N17: 1 | O17: 1800 | P17: =+Tabla35[[#This Row],[P Generada (KW)2]]*Tabla35[[#This Row],[GE Oficinas (Respaldo)]] -> 1800 | Q17: 426224 | R17: 358028 | S17: =+Tabla35[[#This Row],[Cantidad Diesel /kg]]/Tabla35[[#This Row],[Cantidad Diesel /L]] -> 0.83999962 | T17: 30 | U17: No se especifica | V17: No se especifica | X17: =Tabla35[[#This Row],[Total Generado KW]]+Tabla35[[#This Row],[Total Generado KW2]] -> 57800 | Y17: =Tabla35[[#This Row],[Total Generado KW]]/1.5 -> 37333.333 | AF17: 245 | AG17: 310 | AH17: 50 | AI17: 50 | AJ17: 40 | AK17: 40 | AL17: -33.366358 | AM17: -70.673941 | AP17: Ascenty | AQ17: =+COUNTIFS(Tabla35[Titular],AP17,Tabla35[Estado del Proyecto],"Aprobado") -> 2 | AR17: =+SUMIFS(Tabla35[Inversión (MMU$)],Tabla35[Titular],AP17,Tabla35[Estado del Proyecto],"Aprobado") -> 220
A18: Centro de Almacenamiento de Datos Padre Hurtado | B18: Ver | C18: Metropolitana | D18: Padre Hurtado | E18: Amazon | F18: 205 | G18: Aprobado | H18: 473.82668 | I18: 45300.625 | J18: ORBE Consultores | K18: 10 | L18: 2800 | M18: =Tabla35[[#This Row],[P Generada (KW)]]*Tabla35[[#This Row],[GE Salas (Principal)]] -> 28000 | N18: 1 | O18: 1050 | P18: =+Tabla35[[#This Row],[P Generada (KW)2]]*Tabla35[[#This Row],[GE Oficinas (Respaldo)]] -> 1050 | Q18: 216205 | R18: 179883 | S18: =+Tabla35[[#This Row],[Cantidad Diesel /kg]]/Tabla35[[#This Row],[Cantidad Diesel /L]] -> 0.83200204 | T18: 30 | U18: No se especifica | V18: No se especifica | X18: =Tabla35[[#This Row],[Total Generado KW]]+Tabla35[[#This Row],[Total Generado KW2]] -> 29050 | Y18: =Tabla35[[#This Row],[Total Generado KW]]/1.5 -> 18666.667 | AF18: 245 | AG18: 310 | AH18: 25 | AI18: 25 | AJ18: 40 | AK18: 40 | AL18: -33.373394 | AM18: -70.660089 | AP18: ODATA | AQ18: =+COUNTIFS(Tabla35[Titular],AP18,Tabla35[Estado del Proyecto],"Aprobado") -> 1 | AR18: =+SUMIFS(Tabla35[Inversión (MMU$)],Tabla35[Titular],AP18,Tabla35[Estado del Proyecto],"Aprobado") -> 271
A19: Centro de Almacenamiento de Datos Puente Alto | B19: Ver | C19: Metropolitana | D19: Puente Alto | E19: Amazon | F19: 205 | G19: Desistido | H19: 179.7812 | I19: 44956.625 | J19: ORBE Consultores | K19: 20 | L19: 2800 | M19: =Tabla35[[#This Row],[P Generada (KW)]]*Tabla35[[#This Row],[GE Salas (Principal)]] -> 56000 | N19: 1 | O19: 1800 | P19: =+Tabla35[[#This Row],[P Generada (KW)2]]*Tabla35[[#This Row],[GE Oficinas (Respaldo)]] -> 1800 | Q19: 426224 | R19: 358028 | S19: =+Tabla35[[#This Row],[Cantidad Diesel /kg]]/Tabla35[[#This Row],[Cantidad Diesel /L]] -> 0.83999962 | T19: 30 | U19: No se especifica | V19: No se especifica | X19: =Tabla35[[#This Row],[Total Generado KW]]+Tabla35[[#This Row],[Total Generado KW2]] -> 57800 | Y19: =Tabla35[[#This Row],[Total Generado KW]]/1.5 -> 37333.333 | AF19: 245 | AG19: 310 | AH19: 25 | AI19: 25 | AJ19: 40 | AK19: 40 | AL19: -33.556681 | AM19: -70.813233
A20: Scala Data Center Curauma | B20: Ver | C20: Valparaíso | D20: Valparaíso | E20: SCALA | F20: 65 | G20: Aprobado | H20: 177.81226 | I20: 44816.625 | J20: GIZA Ingeniería | K20: 6 | L20: 2750 | M20: =Tabla35[[#This Row],[P Generada (KW)]]*Tabla35[[#This Row],[GE Salas (Principal)]] -> 16500 | N20: 1 | O20: 400 | P20: =Tabla35[[#This Row],[P Generada (KW)2]]*Tabla35[[#This Row],[GE Oficinas (Respaldo)]] -> 400 | Q20: 218000 | R20: 185300 | S20: =+Tabla35[[#This Row],[Cantidad Diesel /kg]]/Tabla35[[#This Row],[Cantidad Diesel /L]] -> 0.85 | T20: 25 | U20: 5 | V20: 1550 | W20: =Tabla35[[#This Row],[Consumo (KW)3]]*Tabla35[[#This Row],[Cantidad Chillers]] -> 7750 | X20: =Tabla35[[#This Row],[Total Generado KW]]+Tabla35[[#This Row],[Total Generado KW2]] -> 16900 | Y20: =Tabla35[[#This Row],[Total Generado KW]]/1.5 -> 11000 | Z20: =+Tabla35[[#This Row],[MO Contrucción Promedio]]/Tabla35[[#This Row],[Total Generado KW]] -> 0.0072727273 | AA20: =+Tabla35[[#This Row],[MO Contrucción Máximo]]/Tabla35[[#This Row],[Total Generado KW]] -> 0.012121212 | AB20: =+Tabla35[[#This Row],[MO Operación Promedio]]/Tabla35[[#This Row],[Total Generado KW]] -> 0.00060606061 | AC20: =+Tabla35[[#This Row],[MO Operación Máximo]]/Tabla35[[#This Row],[Total Generado KW]] -> 0.0012121212 | AD20: =+Tabla35[[#This Row],[MO Cierre Promedio]]/Tabla35[[#This Row],[Total Generado KW]] -> 0.0012121212 | AE20: =+Tabla35[[#This Row],[MO Cierre Máximo]]/Tabla35[[#This Row],[Total Generado KW]] -> 0.0024242424 | AF20: 120 | AG20: 200 | AH20: 10 | AI20: 20 | AJ20: 20 | AK20: 40 | AL20: -33.135973 | AM20: -71.558861 | AP20: Sonda S.A. | AQ20: =+COUNTIFS(Tabla35[Titular],AP20,Tabla35[Estado del Proyecto],"Aprobado") -> 1 | AR20: =+SUMIFS(Tabla35[Inversión (MMU$)],Tabla35[Titular],AP20,Tabla35[Estado del Proyecto],"Aprobado") -> 125
A21: Scala Data Center Curauma | B21: Ver | C21: Valparaíso | D21: Valparaíso | E21: SCALA | F21: PEND | G21: 4 etapas | I21: 44816.625 | J21: GIZA Ingeniería | K21: 34 | L21: 2750 | M21: =Tabla35[[#This Row],[P Generada (KW)]]*Tabla35[[#This Row],[GE Salas (Principal)]] -> 93500 | N21: 4 | O21: 400 | P21: =Tabla35[[#This Row],[P Generada (KW)2]]*Tabla35[[#This Row],[GE Oficinas (Respaldo)]] -> 1600 | Q21: 1222000 | R21: 1038700 | S21: =+Tabla35[[#This Row],[Cantidad Diesel /kg]]/Tabla35[[#This Row],[Cantidad Diesel /L]] -> 0.85 | T21: 25 | U21: 30 | V21: 1550 | W21: =Tabla35[[#This Row],[Consumo (KW)3]]*Tabla35[[#This Row],[Cantidad Chillers]] -> 46500 | X21: =Tabla35[[#This Row],[Total Generado KW]]+Tabla35[[#This Row],[Total Generado KW2]] -> 95100 | Y21: =Tabla35[[#This Row],[Total Generado KW]]/1.5 -> 62333.333 | AL21: 33.137984 | AM21: -71.560931 | AP21: Dataluna | AQ21: 3 | AR21: =+SUMIFS(Tabla35[Inversión (MMU$)],Tabla35[Titular],AP21,Tabla35[Estado del Proyecto],"Aprobado")+H30 -> 358.16522
